---
title: Excepciones en Python
---
import {Cons, ProCons, Pros} from "/src/components/cajitas/ProCons";
import Tabs from "@theme/Tabs";
import TabItem from "@theme/TabItem";
import References from "/src/components/ReferencesComponent";
import ReadingTime from '/src/components/ReadingTime';
import BoxedTabs from '@site/src/components/cajitas/BoxedTabs'

<ReadingTime/>

Al igual que **Kotlin**, Python también tiene un manejo de excepciones basado en bloques `try-catch` (o `try-except`), aunque con algunas diferencias en su sintaxis y convenciones. A continuación, se destacan las similitudes y diferencias clave.

## Lanzar Excepciones

En ambos lenguajes, se puede lanzar una excepción usando `throw` en Kotlin y `raise` en Python. Sin embargo, existe una diferencia importante en las convenciones. En Python, se usa la palabra **`Error`** en los nombres de las excepciones para indicar un fallo esperado, como `ValueError`, mientras que en Kotlin **`Error`** denota algo más grave y que típicamente no debería capturarse, como en el caso de errores fatales del sistema (`OutOfMemoryError`).

<BoxedTabs>
    <TabItem label={"Código esencial"} value={"Código esencial"}>
        ```python showLineNumbers
        raise ValueError("Cannot divide by zero")
        ```
    </TabItem>
    <TabItem label={"Código completo"} value={"Código completo"}>
        ```python showLineNumbers title="src/intro/exceptions/divide.py"
        def divide(a: int, b: int) -> int:
            if b == 0:
                raise ValueError("Cannot divide by zero")
            return a // b

        if __name__ == '__main__':
            print(divide(10, 2))
            print(divide(10, 0))
            # Output:
            # 5
            # Traceback (most recent call last):
            # ...
            # ValueError: Cannot divide by zero
        ```
    </TabItem>
</BoxedTabs>

En Kotlin, las excepciones que lanzamos son generalmente subclases de `Exception`, mientras que `Error` en Kotlin se refiere a fallos catastróficos que el programa no debería intentar manejar.

## Capturar Excepciones

Ambos lenguajes usan `try-catch` (o `try-except` en Python) para capturar excepciones. Sin embargo, en Python se puede usar un bloque `else` para definir código que debe ejecutarse si **no** se lanza ninguna excepción, una característica que no existe en Kotlin.

<BoxedTabs>
    <TabItem label={"Código esencial"} value={"Código esencial"}>
        ```python showLineNumbers
        try:
            return divide(a, b)
        except ValueError as e:
            return None
        ```
    </TabItem>
    <TabItem label={"Código completo"} value={"Código completo"}>
        ```python showLineNumbers title="src/intro/exceptions/safe_divide.py"
        from typing import Optional

        from intro.exceptions.divide import divide


        def safe_divide(a: int, b: int) -> Optional[int]:
            try:
                return divide(a, b)
            except ValueError as e:
                return None

        if __name__ == '__main__':
            print(safe_divide(10, 2))
            print(safe_divide(10, 0))
            # Output:
            # 5
            # None
        ```
    </TabItem>
</BoxedTabs>

## Bloque `finally`

En ambos lenguajes, el bloque `finally` se ejecuta siempre, independientemente de si una excepción fue lanzada o no. Esto se utiliza típicamente para la liberación de recursos.

<BoxedTabs>
    <TabItem label={"Código esencial"} value={"Código esencial"}>
        ```python showLineNumbers title="playground.py"
        try:
            # Operation that may raise an exception
        except Exception as e:
            # Handle exception
        finally:
            # Cleanup resources
        ```
    </TabItem>
    <TabItem label={"Código completo"} value={"Código completo"}>
        ```python showLineNumbers title="playground.py"
        def read_file(path: str) -> None:
            reader = None
            try:
                reader = open(path, 'r')
                content = reader.read()
                print("File content:")
                print(content)
            except FileNotFoundError as e:
                print(f"Error: File not found. {e}")
            except PermissionError as e:
                print(f"Error: Permission denied. {e}")
            finally:
                if reader and not reader.closed:
                    reader.close()
                    print("File closed")
        ```
    </TabItem>
    <TabItem label={"Código completo (mejorado)"} value={"Código completo (mejorado)"}>
        ```python showLineNumbers title="playground.py"
        def read_file(path: str) -> None:
            try:
                with open(path, 'r') as reader:
                    content = reader.read()
                    print("File content:\n", content)
            except FileNotFoundError:
                print(f"Error: File '{path}' not found.")
            except PermissionError:
                print(f"Error: Permission denied for '{path}'.")
        ```

        :::info Explicación de las mejoras

        - Se utiliza un bloque `with` para abrir el archivo, lo que garantiza que se cierre automáticamente al salir del bloque.
        - Se eliminó la verificación manual de si el archivo está cerrado, ya que el bloque `with` se encarga de cerrarlo automáticamente.

        :::
    </TabItem>
</BoxedTabs>

## Bloque `else`

En Python, además de `try`, `except`, y `finally`, existe el bloque `else`, que se ejecuta si **no** se lanza ninguna excepción en el bloque `try`. Este bloque es útil para separar el código que se ejecuta solo cuando el `try` es exitoso del manejo de errores en el bloque `except`, lo que mejora la claridad del flujo de control y hace el código más explícito.

<BoxedTabs>
<TabItem label="Ejemplo de uso" value="Ejemplo de uso">
```python showLineNumbers
def process_file(path: str) -> None:
    try:
        with open(path, 'r') as reader:
            content = reader.read()
    except FileNotFoundError:
        print("Error: El archivo no fue encontrado.")
    except PermissionError:
        print("Error: No tienes permiso para abrir este archivo.")
    else:
        print("Archivo procesado exitosamente:")
        print(content)
    finally:
        print("Proceso terminado.")
```
</TabItem>
</BoxedTabs>

### Explicación del bloque `else`

- **Ubicación y propósito**: El bloque `else` se coloca entre el `except` y `finally`. Solo se ejecuta si no ocurre ninguna excepción en el bloque `try`, lo que lo convierte en un espacio seguro para código que solo debe ejecutarse en una ejecución sin errores.
- **Claridad en el flujo de control**: Al usar `else`, el código mantiene un flujo claro y evita la confusión de que el bloque `finally` solo ejecuta limpieza o cierre de recursos, y no ejecución de lógica adicional.

### Ejemplo práctico

En este ejemplo, el bloque `else` se usa para asegurar que el contenido del archivo solo se imprime si la lectura fue exitosa, manteniendo la separación entre el manejo de errores (`except`) y el procesamiento de datos (`else`):

```python
def analyze_data_file(path: str) -> None:
    try:
        with open(path, 'r') as file:
            data = file.read()
    except FileNotFoundError:
        print("Error: Archivo no encontrado.")
    except PermissionError:
        print("Error: Permiso denegado.")
    else:
        print("Análisis de datos completo:\n", data)
    finally:
        print("Ejecución finalizada.")
```

Aquí, `else` asegura que el bloque de análisis (`print("Análisis de datos completo...")`) se ejecuta únicamente en caso de éxito, facilitando la lectura y minimizando errores en el manejo de excepciones y control de flujo.

## Excepciones Personalizadas

En ambos lenguajes, puedes definir excepciones personalizadas. En Python, se sigue la convención de agregar "Error" al nombre de la excepción, mientras que en Kotlin las excepciones suelen derivar de `Exception`.

<BoxedTabs>
    <TabItem label={"Código esencial"} value={"Código esencial"}>
        ```python showLineNumbers
        class StopLovingError(Exception):
            def __init__(self, message: str):
                super().__init__(message)

        def validate_age(age: int) -> None:
            if age >= 70:
                raise StopLovingError("And, darling, I will be loving you 'til we're 70")
        ```
    </TabItem>
    <TabItem label={"Código completo"} value={"Código completo"}>
        ```python showLineNumbers title="exceptions/stop_loving_error.py"
        class StopLovingError(Exception):
            def __init__(self, message: str):
                super().__init__(message)
        ```

        ```python showLineNumbers title="exceptions/stop_loving_error.py"
        from exceptions.stop_loving_error import StopLovingError


        def validate_age(age: int) -> None:
            if age >= 70:
                raise StopLovingError("And, darling, I will be loving you 'til we're 70")
        ```
    </TabItem>
</BoxedTabs>

## Comparación final

| Aspecto                            | Kotlin                                                                       | Python                                                                                                    |
|------------------------------------|------------------------------------------------------------------------------|-----------------------------------------------------------------------------------------------------------|
| **Lanzar Excepciones**             | `throw` para lanzar excepciones, como `IllegalArgumentException`.            | `raise` para lanzar excepciones, como `ValueError`.                                                       |
| **Convención de nombres**          | `Error` se reserva para fallos críticos, como `OutOfMemoryError`.            | Las excepciones personalizadas y del sistema terminan en **`Error`** (ej. `ValueError`, `TypeError`).     |
| **Capturar Excepciones**           | `try-catch` para capturar excepciones.                                       | `try-except` para capturar excepciones. Incluye un bloque `else`.                                         |
| **Bloque `finally`**               | Ejecuta siempre, independientemente de si se lanzó una excepción.            | Funciona igual que en Kotlin, siempre se ejecuta.                                                         |
| **Excepciones Personalizadas**     | Heredan de `Exception`. Ejemplo: `class CustomException : Exception()`.      | Heredan de `Exception` con la convención de terminar en `Error`. Ejemplo: `class CustomError(Exception)`. |
| **Else en Captura de Excepciones** | No disponible.                                                               | `else` se ejecuta si no se lanza ninguna excepción en el bloque `try`.                                    |
| **Chequeo de Excepciones**         | No tiene excepciones chequeadas.                                             | Tampoco tiene excepciones chequeadas.                                                                     |
| **Manejo de errores**              | Uso preferido de tipos anulables (`nullable`) y `Result`.                    | Se manejan principalmente con excepciones.                                                                |
| **Propagación de Excepciones**     | Las excepciones se propagan si no se capturan, sin necesidad de declararlas. | Funciona de manera similar a Kotlin.                                                                      |

<References references={[
    {
        title: "4. Expecting the Unexpected",
        bookTitle: "Python 3 Object-Oriented Programming",
        pages: "99-126",
        location: "Livery Place, Birmingham",
        publisher: "Packt Publishing",
        year: "2018",
        type: "book",
        author: 'Dusty Phillips',
        edition: 'Third Edition',
    },
]}/>
